<robot name="robosim">

  <link name="base_link">
  </link>

  <joint name="base_to_torso" type="fixed">
    <parent link="base_link"/>
    <child link="torso"/>
    <origin xyz="0 0.0 0.0" rpy="3.14159 0.0 0.0"/>
  </joint>

   <link name="torso">
      <inertial>
        <mass value="46.658335" />
        <origin xyz="0.040288 -0.001937 -0.073574" rpy="0 0 0" />
        <inertia ixx="1.272134" ixy="0.008890" ixz="-0.139427" iyy="2.568776" iyz="0.000325" izz="3.086984" />
      </inertial>
      <visual>
        <origin xyz="0 0 0" rpy="0 0 0" />
        <geometry>
           <mesh filename="./stl/robosim_chassis.stl" scale="1 1 1" />
        </geometry>
        <material name="blue">
	      <color rgba="0 0 .8 1" />
        </material>
      </visual>
      <collision group="default">
        <origin rpy="0 0 0" xyz="0 0 0"/>
        <geometry>
           <box size="0.257 0.50 0.238"/>
        </geometry>
      </collision>
      <collision group="other">
        <origin rpy="0 0 0" xyz="0 0 0"/>
        <geometry>
           <box size="0.93 0.230 0.238"/>
        </geometry>
      </collision>
      <collision group="other">
        <origin rpy="0 0 -0.38153" xyz="0.25393 0.075769 0"/>
        <geometry>
           <box size="0.36257 0.23 0.238"/>
        </geometry>
      </collision>
      <collision group="other">
        <origin rpy="0 0 0.38153" xyz="-0.25393 0.075769 0"/>
        <geometry>
           <box size="0.36257 0.23 0.238"/>
        </geometry>
      </collision>
      <collision group="other">
        <origin rpy="0 0 0.38153" xyz="0.25393 -0.075769 0"/>
        <geometry>
           <box size="0.36257 0.23 0.238"/>
        </geometry>
      </collision>
      <collision group="other">
        <origin rpy="0 0 -0.38153" xyz="-0.25393 -0.075769 0"/>
        <geometry>
           <box size="0.36257 0.23 0.238"/>
        </geometry>
      </collision>
      <collision group="other">
        <origin rpy="0.000000 -0.383972 0.000000" xyz="0.417050 0.000000 -0.158640"/>
        <geometry>
          <cylinder length="0.144" radius="0.05"/>
        </geometry>
      </collision>
   </link>

   <link name="sled">
      <inertial>
        <mass value="2.768775" />
        <origin xyz="0.000000 0.000000 0.146762" rpy="0 0 0" />
        <inertia ixx="0.034856" ixy="0.000007" ixz="-0.000002" iyy="0.082427" iyz="0.000000" izz="0.105853" />
      </inertial>
      <visual>
        <origin xyz="0.000000 0 0" rpy="0 0 0" />
        <geometry>
           <mesh filename="./stl/robosim_sled.stl" scale="1 1 1" />
        </geometry>
      </visual>
      <collision group="other">
        <origin rpy="0 0 0" xyz="0 0 0"/>
        <geometry>
          <mesh filename="./stl/robosim_sled_coll.stl" scale="1 1 1" />
        </geometry>
      </collision>
   </link>

   <joint name="sled_joint" type="fixed">
      <origin xyz="0.0 0.0 0.21"  rpy="1.570796 0.00 0.00" />
      <parent link="torso" />
      <child link="sled" />
   </joint>

   <link name="limb1_link0">
      <inertial>
        <mass value="0.000000" />
        <origin xyz="0.000000 0.000000 0.000000" rpy="0 0 0" />
        <inertia ixx="0.000000" ixy="0.000000" ixz="0.000000" iyy="0.000000" iyz="0.000000" izz="0.000000" />
      </inertial>
      <visual>
        <origin xyz="0.000000 0 0" rpy="0 0 0" />
        <geometry>
           <mesh filename="./stl/robosim_fts.stl" scale="1 1 1" />
        </geometry>
      </visual>
      <collision group="other">
        <origin rpy="3.1415 -1.57080 0" xyz="-.025 0 0"/>
        <geometry>
          <cylinder length="0.145" radius="0.05"/>
        </geometry>
      </collision>
   </link>

   <link name="limb1_link1">
      <inertial>
        <mass value="0.428770" />
        <origin xyz="-0.050402 0.012816 0.000000" rpy="0 0 0" />
        <inertia ixx="0.000670" ixy="0.000062" ixz="0.000000" iyy="0.000955" iyz="0.000000" izz=" 0.000726" />
      </inertial>
      <visual>
        <origin xyz="0.000000 0 0" rpy="0 0 0" />
        <geometry>
           <mesh filename="./stl/robosim_pitch_link.stl" scale="1 1 1" />
        </geometry>
      </visual>
      <collision group="other">
        <origin rpy="3.1415 -1.57080 0" xyz="-0.07 0 0"/>
        <geometry>
          <cylinder length="0.07" radius="0.055"/>
        </geometry>
      </collision>
   </link>

   <link name="limb1_link2">
      <inertial>
        <mass value="4.078540" />
        <origin xyz="0.066970 -0.090099 -0.000084" rpy="0 0 0" />
        <inertia ixx="0.010580" ixy="-0.008765" ixz="-0.000002" iyy="0.025014" iyz="0.000007" izz="0.031182" />
      </inertial>
      <visual>
        <origin xyz="0.000000 0 0" rpy="0 0 0" />
        <geometry>
           <mesh filename="./stl/robosim_roll_link.stl" scale="1 1 1" />
        </geometry>
      </visual>
      <collision group="other">
        <origin rpy="3.1415 -1.57080 0" xyz="0.065 -0.12 0"/>
        <geometry>
          <cylinder length="0.24" radius="0.055"/>
        </geometry>
      </collision>
      <collision group="other">
        <origin rpy="1.57080 1.57080 0.0" xyz="0.0 -0.035 0"/>
        <geometry>
          <cylinder length="0.075" radius="0.055"/>
        </geometry>
      </collision>
   </link>

   <link name="limb1_link3">
      <inertial>
        <mass value="0.428770" />
        <origin xyz="-0.050402 0.012816 0.000000" rpy="0 0 0" />
        <inertia ixx="0.000670" ixy="0.000062" ixz="0.000000" iyy="0.000955" iyz="0.000000" izz=" 0.000726" />
      </inertial>
      <visual>
        <origin xyz="0.000000 0 0" rpy="0 0 0" />
        <geometry>
           <mesh filename="./stl/robosim_pitch_link.stl" scale="1 1 1" />
        </geometry>
      </visual>
      <collision group="other">
        <origin rpy="3.1415 -1.57080 0" xyz="-0.07 0 0"/>
        <geometry>
          <cylinder length="0.07" radius="0.055"/>
        </geometry>
      </collision>
   </link>

   <link name="limb1_link4">
      <inertial>
        <mass value="4.078540" />
        <origin xyz="0.066970 -0.090099 -0.000084" rpy="0 0 0" />
        <inertia ixx="0.010580" ixy="-0.008765" ixz="-0.000002" iyy="0.025014" iyz="0.000007" izz="0.031182" />
      </inertial>
      <visual>
        <origin xyz="0.000000 0 0" rpy="0 0 0" />
        <geometry>
           <mesh filename="./stl/robosim_roll_link.stl" scale="1 1 1" />
        </geometry>
      </visual>
      <collision group="other">
        <origin rpy="3.1415 -1.57080 0" xyz="0.065 -0.12 0"/>
        <geometry>
          <cylinder length="0.24" radius="0.055"/>
        </geometry>
      </collision>
      <collision group="other">
        <origin rpy="1.57080 1.57080 0.0" xyz="0.0 -0.035 0"/>
        <geometry>
          <cylinder length="0.075" radius="0.055"/>
        </geometry>
      </collision>
   </link>

   <link name="limb1_link5">
      <inertial>
        <mass value="0.428770" />
        <origin xyz="-0.050402 0.012816 0.000000" rpy="0 0 0" />
        <inertia ixx="0.000670" ixy="0.000062" ixz="0.000000" iyy="0.000955" iyz="0.000000" izz=" 0.000726" />
      </inertial>
      <visual>
        <origin xyz="0.000000 0 0" rpy="0 0 0" />
        <geometry>
           <mesh filename="./stl/robosim_pitch_link.stl" scale="1 1 1" />
        </geometry>
      </visual>
      <collision group="other">
        <origin rpy="3.1415 -1.57080 0" xyz="-0.07 0 0"/>
        <geometry>
          <cylinder length="0.07" radius="0.055"/>
        </geometry>
      </collision>
   </link>

   <link name="limb1_link6">
      <inertial>
        <mass value="4.078540" />
        <origin xyz="0.066970 -0.090099 -0.000084" rpy="0 0 0" />
        <inertia ixx="0.010580" ixy="-0.008765" ixz="-0.000002" iyy="0.025014" iyz="0.000007" izz="0.031182" />
      </inertial>
      <visual>
        <origin xyz="0.000000 0 0" rpy="0 0 0" />
        <geometry>
           <mesh filename="./stl/robosim_roll_link.stl" scale="1 1 1" />
        </geometry>
      </visual>
      <collision group="other">
        <origin rpy="3.1415 -1.57080 0" xyz="0.105 -0.12 0"/>
        <geometry>
          <cylinder length="0.32" radius="0.055"/>
        </geometry>
      </collision>
      <collision group="other">
        <origin rpy="1.57080 1.57080 0.0" xyz="0.0 -0.035 0"/>
        <geometry>
          <cylinder length="0.075" radius="0.055"/>
        </geometry>
      </collision>
   </link>
  
   <link name="limb1_ftadapter_link">
      <inertial>
        <mass value="0.253735" />
        <origin xyz="-0.00531 -0.00060 -0.001873" rpy="0 0 0" />
        <inertia ixx="0.00042" ixy="0.00000" ixz="0.0000" iyy="0.00024" iyz="0.00000" izz="0.00023" />
      </inertial>
      <visual>
         <origin xyz="0 0 0" rpy="0 0 0" />
         <geometry>
            <mesh filename="./stl/robosim_ft_adapter.stl" scale="1 1 1" />
         </geometry>
      </visual>   
   </link>

   <link name="limb1_ft_link">
      <inertial>
        <mass value="0.195418" />
        <origin xyz="-0.000135 0.000118 0.000084" rpy="0 0 0" />
        <inertia ixx="0.000086" ixy="0.000" ixz="0.0000" iyy="0.000056" iyz="0.000000" izz="0.000057" />
      </inertial>
      <visual>
         <origin xyz="0 0 0" rpy="0 0 0" />
         <geometry>
            <mesh filename="./stl/robosim_force_torque_sensor.stl" scale="1 1 1" />
         </geometry>
      </visual>   
   </link>

   <link name="limb1_link7">
      <inertial>
        <mass value="3.1775" />
        <origin xyz="-0.005260 0.042308 0.000088" rpy="0 0 0" />
        <inertia ixx="0.010977" ixy="0.000702" ixz="0.000026" iyy="0.005330" iyz="-0.000028" izz=" 0.011405" />
      </inertial>
      <visual>
        <origin xyz="0.12024 0 0" rpy="0 0 0" />
        <geometry>
           <mesh filename="./stl/robosim_wheel_mount.stl" scale="1 1 1" />
        </geometry>
      </visual>
      <collision group="other">
        <origin rpy="-1.57080 0 0" xyz="0.12024 0.02 0"/>
        <geometry>
          <cylinder length="0.175" radius="0.0545"/>
        </geometry>
      </collision>
   </link>

  <link name="limb1_link8">
    <inertial>
      <mass value="1.499326" />
      <origin xyz="0.0 0.0 -0.000229" rpy="0 0 0" />
      <inertia ixx="0.006378" ixy="0.000000" ixz="0.000000" iyy="0.006377" iyz="0.000000" izz="0.009155" />
     </inertial>
    <visual>
      <origin xyz="0.0 0 0" rpy="0 0 0" />
      <geometry>
         <mesh filename="./stl/robosim_wheel.stl" scale="1 1 1" />
      </geometry>
    </visual>
    <collision group="other">
      <origin xyz="0.0 0 0" rpy="0 0 0" />
      <geometry>
         <cylinder length="0.123" radius="0.12" />
      </geometry>
    </collision>
  </link>

   <joint name="limb1_joint0" type="fixed" >
      <origin xyz="0.29326 0.20940 0.03650"  rpy="0.00000 -1.57080 -0.26180" />
      <parent link="torso" />
      <child link="limb1_link0" />
      <axis xyz="0 0 1" />
      <limit effort="1000.0" lower="-3.4906" upper="3.4906" velocity="0.5"/>
      <dynamics damping="0" friction="0"/>
   </joint>

   <joint name="limb1_joint1" type="revolute">
      <origin xyz="0.17203 0.00000 0.00000"  rpy="3.14159 -0.00000 0.00000" />
      <axis xyz="1 0 0" />
      <parent link="limb1_link0" />
      <child link="limb1_link1" />
      <limit effort="1000.0" lower="-6.283185" upper="6.283185" velocity="0.5"/>
      <dynamics damping="1.000000" friction="10.000000"/>
   </joint>

   <joint name="limb1_joint2" type="revolute">
      <origin xyz="0.00000 0.00000 0.00000"  rpy="0.00000 -0.00000 0.00000" />
      <axis xyz="0 -1 0" />
      <parent link="limb1_link1" />
      <child link="limb1_link2" />
      <limit effort="1000.0" lower="-6.283185" upper="6.283185" velocity="0.5"/>
      <dynamics damping="1.000000" friction="10.000000"/>
   </joint>

   <joint name="limb1_joint3" type="revolute">
      <origin xyz="0.28650 -0.11700 0.00000"  rpy="0.00000 -0.00000 0.00000" />
      <axis xyz="1 0 0" />
      <parent link="limb1_link2" />
      <child link="limb1_link3" />
      <limit effort="1000.0" lower="-6.283185" upper="6.283185" velocity="0.5"/>
      <dynamics damping="1.000000" friction="10.000000"/>
   </joint>

   <joint name="limb1_joint4" type="revolute">
      <origin xyz="0.00000 0.00000 0.00000"  rpy="0.00000 -0.00000 0.00000" />
      <axis xyz="0 -1 0" />
      <parent link="limb1_link3" />
      <child link="limb1_link4" />
      <limit effort="1000.0" lower="-6.283185" upper="6.283185" velocity="0.5"/>
      <dynamics damping="1.000000" friction="10.000000"/>
   </joint>

   <joint name="limb1_joint5" type="revolute">
      <origin xyz="0.28650 -0.11700 0.00000"  rpy="0.00000 -0.00000 0.00000" />
      <axis xyz="1 0 0" />
      <parent link="limb1_link4" />
      <child link="limb1_link5" />
      <limit effort="1000.0" lower="-6.283185" upper="6.283185" velocity="0.5"/>
      <dynamics damping="1.000000" friction="10.000000"/>
   </joint>

   <joint name="limb1_joint6" type="revolute">
      <origin xyz="0.00000 0.00000 0.00000"  rpy="0.00000 -0.00000 0.00000" />
      <axis xyz="0 -1 0" />
      <parent link="limb1_link5" />
      <child link="limb1_link6" />
      <limit effort="1000.0" lower="-6.283185" upper="6.283185" velocity="0.5"/>
      <dynamics damping="1.000000" friction="10.000000"/>
   </joint>
  
   <joint name="limb1_ftadapter_joint" type="fixed">
      <origin xyz="0.20739 -0.121 0.0"  rpy="0.00000 0.00000 0.00000" />
      <axis xyz="1 0 0" />
      <parent link="limb1_link6" />
      <child link="limb1_ftadapter_link" />
   </joint>  

   <joint name="limb1_ft_joint" type="fixed">
      <origin xyz="0.0263755 0.0 0.0"  rpy="0.00000 0.00000 0.00000" />
      <axis xyz="1 0 0" />
      <parent link="limb1_ftadapter_link" />
      <child link="limb1_ft_link" />
   </joint>

   <joint name="limb1_joint7" type="revolute">
      <origin xyz="0.19250 -0.11700 0.00000"  rpy="0.00000 -0.00000 0.00000" />
      <axis xyz="1 0 0" />
      <parent link="limb1_link6" />
      <child link="limb1_link7" />
      <limit effort="1000.0" lower="-6.283185" upper="6.283185" velocity="0.5"/>
      <dynamics damping="1.000000" friction="10.000000"/>
   </joint>

   <joint name="limb1_joint8" type="revolute">
      <origin xyz="0.12024 0.172 0.0"  rpy="-1.57 0.0 0.00" />
      <axis xyz="0 0 1" />
      <parent link="limb1_link7" />
      <child link="limb1_link8" />
      <limit effort="1000.0" lower="-2e19" upper="2e19" velocity="0.5"/>
      <dynamics damping="1.000000" friction="10.000000"/>
   </joint>

   <link name="limb2_link0">
      <inertial>
        <mass value="0.000000" />
        <origin xyz="0.000000 0.000000 0.000000" rpy="0 0 0" />
        <inertia ixx="0.000000" ixy="0.000000" ixz="0.000000" iyy="0.000000" iyz="0.000000" izz="0.000000" />
      </inertial>
      <visual>
        <origin xyz="0.000000 0 0" rpy="0 0 0" />
        <geometry>
           <mesh filename="./stl/robosim_fts.stl" scale="1 1 1" />
        </geometry>
      </visual>
      <collision group="other">
        <origin rpy="3.1415 -1.57080 0" xyz="-.025 0 0"/>
        <geometry>
          <cylinder length="0.145" radius="0.05"/>
        </geometry>
      </collision>
   </link>

   <link name="limb2_link1">
      <inertial>
        <mass value="0.428770" />
        <origin xyz="-0.050402 0.012816 0.000000" rpy="0 0 0" />
        <inertia ixx="0.000670" ixy="0.000062" ixz="0.000000" iyy="0.000955" iyz="0.000000" izz=" 0.000726" />
      </inertial>
      <visual>
        <origin xyz="0.000000 0 0" rpy="0 0 0" />
        <geometry>
           <mesh filename="./stl/robosim_pitch_link.stl" scale="1 1 1" />
        </geometry>
      </visual>
      <collision group="other">
        <origin rpy="3.1415 -1.57080 0" xyz="-0.07 0 0"/>
        <geometry>
          <cylinder length="0.07" radius="0.055"/>
        </geometry>
      </collision>
   </link>

   <link name="limb2_link2">
      <inertial>
        <mass value="4.078540" />
        <origin xyz="0.066970 -0.090099 -0.000084" rpy="0 0 0" />
        <inertia ixx="0.010580" ixy="-0.008765" ixz="-0.000002" iyy="0.025014" iyz="0.000007" izz="0.031182" />
      </inertial>
      <visual>
        <origin xyz="0.000000 0 0" rpy="0 0 0" />
        <geometry>
           <mesh filename="./stl/robosim_roll_link.stl" scale="1 1 1" />
        </geometry>
      </visual>
      <collision group="other">
        <origin rpy="3.1415 -1.57080 0" xyz="0.065 -0.12 0"/>
        <geometry>
          <cylinder length="0.24" radius="0.055"/>
        </geometry>
      </collision>
      <collision group="other">
        <origin rpy="1.57080 1.57080 0.0" xyz="0.0 -0.035 0"/>
        <geometry>
          <cylinder length="0.075" radius="0.055"/>
        </geometry>
      </collision>
   </link>

   <link name="limb2_link3">
      <inertial>
        <mass value="0.428770" />
        <origin xyz="-0.050402 0.012816 0.000000" rpy="0 0 0" />
        <inertia ixx="0.000670" ixy="0.000062" ixz="0.000000" iyy="0.000955" iyz="0.000000" izz=" 0.000726" />
      </inertial>
      <visual>
        <origin xyz="0.000000 0 0" rpy="0 0 0" />
        <geometry>
           <mesh filename="./stl/robosim_pitch_link.stl" scale="1 1 1" />
        </geometry>
      </visual>
      <collision group="other">
        <origin rpy="3.1415 -1.57080 0" xyz="-0.07 0 0"/>
        <geometry>
          <cylinder length="0.07" radius="0.055"/>
        </geometry>
      </collision>
   </link>

   <link name="limb2_link4">
      <inertial>
        <mass value="4.078540" />
        <origin xyz="0.066970 -0.090099 -0.000084" rpy="0 0 0" />
        <inertia ixx="0.010580" ixy="-0.008765" ixz="-0.000002" iyy="0.025014" iyz="0.000007" izz="0.031182" />
      </inertial>
      <visual>
        <origin xyz="0.000000 0 0" rpy="0 0 0" />
        <geometry>
           <mesh filename="./stl/robosim_roll_link.stl" scale="1 1 1" />
        </geometry>
      </visual>
      <collision group="other">
        <origin rpy="3.1415 -1.57080 0" xyz="0.065 -0.12 0"/>
        <geometry>
          <cylinder length="0.24" radius="0.055"/>
        </geometry>
      </collision>
      <collision group="other">
        <origin rpy="1.57080 1.57080 0.0" xyz="0.0 -0.035 0"/>
        <geometry>
          <cylinder length="0.075" radius="0.055"/>
        </geometry>
      </collision>
   </link>

   <link name="limb2_link5">
      <inertial>
        <mass value="0.428770" />
        <origin xyz="-0.050402 0.012816 0.000000" rpy="0 0 0" />
        <inertia ixx="0.000670" ixy="0.000062" ixz="0.000000" iyy="0.000955" iyz="0.000000" izz=" 0.000726" />
      </inertial>
      <visual>
        <origin xyz="0.000000 0 0" rpy="0 0 0" />
        <geometry>
           <mesh filename="./stl/robosim_pitch_link.stl" scale="1 1 1" />
        </geometry>
      </visual>
      <collision group="other">
        <origin rpy="3.1415 -1.57080 0" xyz="-0.07 0 0"/>
        <geometry>
          <cylinder length="0.07" radius="0.055"/>
        </geometry>
      </collision>
   </link>

   <link name="limb2_link6">
      <inertial>
        <mass value="4.078540" />
        <origin xyz="0.066970 -0.090099 -0.000084" rpy="0 0 0" />
        <inertia ixx="0.010580" ixy="-0.008765" ixz="-0.000002" iyy="0.025014" iyz="0.000007" izz="0.031182" />
      </inertial>
      <visual>
        <origin xyz="0.000000 0 0" rpy="0 0 0" />
        <geometry>
           <mesh filename="./stl/robosim_roll_link_w_wheel.stl" scale="1 1 1" />
        </geometry>
      </visual>
      <collision group="other">
        <origin rpy="3.1415 -1.57080 0" xyz="0.105 -0.12 0"/>
        <geometry>
          <cylinder length="0.32" radius="0.055"/>
        </geometry>
      </collision>
      <collision group="other">
        <origin rpy="1.57080 1.57080 0.0" xyz="0.0 -0.035 0"/>
        <geometry>
          <cylinder length="0.075" radius="0.055"/>
        </geometry>
      </collision>
      <collision group="other">
        <origin rpy="1.57080 1.57080 0.0" xyz="0.0 -0.19 0"/>
        <geometry>
          <cylinder length="0.0375" radius="0.080"/>
        </geometry>
      </collision>
   </link>
   
   <link name="limb2_ftadapter_link">
      <inertial>
        <mass value="0.253735" />
        <origin xyz="-0.00531 -0.00060 -0.001873" rpy="0 0 0" />
        <inertia ixx="0.00042" ixy="0.00000" ixz="0.0000" iyy="0.00024" iyz="0.00000" izz="0.00023" />
      </inertial>
      <visual>
         <origin xyz="0 0 0" rpy="0 0 0" />
         <geometry>
            <mesh filename="./stl/robosim_ft_adapter.stl" scale="1 1 1" />
         </geometry>
      </visual>   
   </link>

   <link name="limb2_ft_link">
      <inertial>
        <mass value="0.195418" />
        <origin xyz="-0.000135 0.000118 0.000084" rpy="0 0 0" />
        <inertia ixx="0.000086" ixy="0.000" ixz="0.0000" iyy="0.000056" iyz="0.000000" izz="0.000057" />
      </inertial>
      <visual>
         <origin xyz="0 0 0" rpy="0 0 0" />
         <geometry>
            <mesh filename="./stl/robosim_force_torque_sensor.stl" scale="1 1 1" />
         </geometry>
      </visual>   
   </link>
   
   <link name="limb2_link7">
      <inertial>
        <mass value="3.1775" />
        <origin xyz="-0.005260 0.042308 0.000088" rpy="0 0 0" />
        <inertia ixx="0.010977" ixy="0.000702" ixz="0.000026" iyy="0.005330" iyz="-0.000028" izz=" 0.011405" />
      </inertial>
      <visual>
        <origin xyz="0.12024 0 0" rpy="0 0 0" />
        <geometry>
           <mesh filename="./stl/robosim_wheel_mount.stl" scale="1 1 1" />
        </geometry>
      </visual>
      <collision group="other">
        <origin rpy="-1.57080 0 0" xyz="0.12024 0.02 0"/>
        <geometry>
          <cylinder length="0.175" radius="0.0545"/>
        </geometry>
      </collision>
   </link>

  <link name="limb2_link8">
    <inertial>
      <mass value="1.499326" />
      <origin xyz="0.0 0.0 -0.000229" rpy="0 0 0" />
      <inertia ixx="0.006378" ixy="0.000000" ixz="0.000000" iyy="0.006377" iyz="0.000000" izz="0.009155" />
    </inertial>
    <visual>
      <origin xyz="0.0 0 0" rpy="0 0 0" />
      <geometry>
         <mesh filename="./stl/robosim_wheel.stl" scale="1 1 1" />
      </geometry>
    </visual>
    <collision group="other">
      <origin xyz="0.0 0 0" rpy="0 0 0" />
      <geometry>
         <cylinder length="0.123" radius="0.12" />
      </geometry>
    </collision>
  </link>

   <joint name="limb2_joint0" type="fixed">
      <origin xyz="-0.29326 0.20940 0.03650"  rpy="0.00000 -1.57080 0.26180" />
      <parent link="torso" />
      <child link="limb2_link0" />
      <axis xyz="0 0 1" />
      <limit effort="1000.0" lower="-3.4906" upper="3.4906" velocity="0.5"/>
      <dynamics damping="0" friction="0"/>
   </joint>

   <joint name="limb2_joint1" type="revolute">
      <origin xyz="0.17203 0.00000 0.00000"  rpy="3.14159 -0.00000 0.00000" />
      <axis xyz="1 0 0" />
      <parent link="limb2_link0" />
      <child link="limb2_link1" />
      <limit effort="1000.0" lower="-6.283185" upper="6.283185" velocity="0.5"/>
      <dynamics damping="1.000000" friction="10.000000"/>
   </joint>

   <joint name="limb2_joint2" type="revolute">
      <origin xyz="0.00000 0.00000 0.00000"  rpy="0.00000 -0.00000 0.00000" />
      <axis xyz="0 -1 0" />
      <parent link="limb2_link1" />
      <child link="limb2_link2" />
      <limit effort="1000.0" lower="-6.283185" upper="6.283185" velocity="0.5"/>
      <dynamics damping="1.000000" friction="10.000000"/>
   </joint>

   <joint name="limb2_joint3" type="revolute">
      <origin xyz="0.28650 -0.11700 0.00000"  rpy="0.00000 -0.00000 0.00000" />
      <axis xyz="1 0 0" />
      <parent link="limb2_link2" />
      <child link="limb2_link3" />
      <limit effort="1000.0" lower="-6.283185" upper="6.283185" velocity="0.5"/>
      <dynamics damping="1.000000" friction="10.000000"/>
   </joint>

   <joint name="limb2_joint4" type="revolute">
      <origin xyz="0.00000 0.00000 0.00000"  rpy="0.00000 -0.00000 0.00000" />
      <axis xyz="0 -1 0" />
      <parent link="limb2_link3" />
      <child link="limb2_link4" />
      <limit effort="1000.0" lower="-6.283185" upper="6.283185" velocity="0.5"/>
      <dynamics damping="1.000000" friction="10.000000"/>
   </joint>

   <joint name="limb2_joint5" type="revolute">
      <origin xyz="0.28650 -0.11700 0.00000"  rpy="0.00000 -0.00000 0.00000" />
      <axis xyz="1 0 0" />
      <parent link="limb2_link4" />
      <child link="limb2_link5" />
      <limit effort="1000.0" lower="-6.283185" upper="6.283185" velocity="0.5"/>
      <dynamics damping="1.000000" friction="10.000000"/>
   </joint>
  
   <joint name="limb2_joint6" type="revolute">
      <origin xyz="0.00000 0.00000 0.00000"  rpy="0.00000 -0.00000 0.00000" />
      <axis xyz="0 -1 0" />
      <parent link="limb2_link5" />
      <child link="limb2_link6" />
      <limit effort="1000.0" lower="-6.283185" upper="6.283185" velocity="0.5"/>
      <dynamics damping="1.000000" friction="10.000000"/>
   </joint>

   <joint name="limb2_ftadapter_joint" type="fixed">
      <origin xyz="0.20739 -0.121 0.0"  rpy="0.00000 0.00000 0.00000" />
      <axis xyz="1 0 0" />
      <parent link="limb2_link6" />
      <child link="limb2_ftadapter_link" />
   </joint>  

   <joint name="limb2_ft_joint" type="fixed">
      <origin xyz="0.0263755 0.0 0.0"  rpy="0.00000 0.00000 0.00000" />
      <axis xyz="1 0 0" />
      <parent link="limb2_ftadapter_link" />
      <child link="limb2_ft_link" />
   </joint>

   <joint name="limb2_joint7" type="revolute">
      <origin xyz="0.19250 -0.11700 0.00000"  rpy="0.00000 -0.00000 0.00000" />
      <axis xyz="1 0 0" />
      <parent link="limb2_link6" />
      <child link="limb2_link7" />
      <limit effort="1000.0" lower="-6.283185" upper="6.283185" velocity="0.5"/>
      <dynamics damping="1.000000" friction="10.000000"/>
   </joint>

   <joint name="limb2_joint8" type="revolute">
      <origin xyz="0.12024 0.172 0.0"  rpy="-1.57 0.0 0.00" />
      <axis xyz="0 0 1" />
      <parent link="limb2_link7" />
      <child link="limb2_link8" />
      <limit effort="1000.0" lower="-2e19" upper="2e19" velocity="0.5"/>
      <dynamics damping="1.000000" friction="10.000000"/>
   </joint>


  <link name="limb3_link0">
      <inertial>
        <mass value="0.000000" />
        <origin xyz="0.000000 0.000000 0.000000" rpy="0 0 0" />
        <inertia ixx="0.000000" ixy="0.000000" ixz="0.000000" iyy="0.000000" iyz="0.000000" izz="0.000000" />
      </inertial>
      <visual>
        <origin xyz="0.000000 0 0" rpy="0 0 0" />
        <geometry>
           <mesh filename="./stl/robosim_fts.stl" scale="1 1 1" />
        </geometry>
      </visual>
      <collision group="other">
        <origin rpy="3.1415 -1.57080 0" xyz="-.025 0 0"/>
        <geometry>
          <cylinder length="0.145" radius="0.05"/>
        </geometry>
      </collision>
   </link>

   <link name="limb3_link1">
      <inertial>
        <mass value="0.428770" />
        <origin xyz="-0.050402 0.012816 0.000000" rpy="0 0 0" />
        <inertia ixx="0.000670" ixy="0.000062" ixz="0.000000" iyy="0.000955" iyz="0.000000" izz=" 0.000726" />
      </inertial>
      <visual>
        <origin xyz="0.000000 0 0" rpy="0 0 0" />
        <geometry>
           <mesh filename="./stl/robosim_pitch_link.stl" scale="1 1 1" />
        </geometry>
      </visual>
      <collision group="other">
        <origin rpy="3.1415 -1.57080 0" xyz="-0.07 0 0"/>
        <geometry>
          <cylinder length="0.07" radius="0.055"/>
        </geometry>
      </collision>
   </link>

   <link name="limb3_link2">
      <inertial>
        <mass value="4.078540" />
        <origin xyz="0.066970 -0.090099 -0.000084" rpy="0 0 0" />
        <inertia ixx="0.010580" ixy="-0.008765" ixz="-0.000002" iyy="0.025014" iyz="0.000007" izz="0.031182" />
      </inertial>
      <visual>
        <origin xyz="0.000000 0 0" rpy="0 0 0" />
        <geometry>
           <mesh filename="./stl/robosim_roll_link.stl" scale="1 1 1" />
        </geometry>
      </visual>
      <collision group="other">
        <origin rpy="3.1415 -1.57080 0" xyz="0.065 -0.12 0"/>
        <geometry>
          <cylinder length="0.24" radius="0.055"/>
        </geometry>
      </collision>
      <collision group="other">
        <origin rpy="1.57080 1.57080 0.0" xyz="0.0 -0.035 0"/>
        <geometry>
          <cylinder length="0.075" radius="0.055"/>
        </geometry>
      </collision>
   </link>

   <link name="limb3_link3">
      <inertial>
        <mass value="0.428770" />
        <origin xyz="-0.050402 0.012816 0.000000" rpy="0 0 0" />
        <inertia ixx="0.000670" ixy="0.000062" ixz="0.000000" iyy="0.000955" iyz="0.000000" izz=" 0.000726" />
      </inertial>
      <visual>
        <origin xyz="0.000000 0 0" rpy="0 0 0" />
        <geometry>
           <mesh filename="./stl/robosim_pitch_link.stl" scale="1 1 1" />
        </geometry>
      </visual>
      <collision group="other">
        <origin rpy="3.1415 -1.57080 0" xyz="-0.07 0 0"/>
        <geometry>
          <cylinder length="0.07" radius="0.055"/>
        </geometry>
      </collision>
   </link>

   <link name="limb3_link4">
      <inertial>
        <mass value="4.078540" />
        <origin xyz="0.066970 -0.090099 -0.000084" rpy="0 0 0" />
        <inertia ixx="0.010580" ixy="-0.008765" ixz="-0.000002" iyy="0.025014" iyz="0.000007" izz="0.031182" />
      </inertial>
      <visual>
        <origin xyz="0.000000 0 0" rpy="0 0 0" />
        <geometry>
           <mesh filename="./stl/robosim_roll_link.stl" scale="1 1 1" />
        </geometry>
      </visual>
      <collision group="other">
        <origin rpy="3.1415 -1.57080 0" xyz="0.065 -0.12 0"/>
        <geometry>
          <cylinder length="0.24" radius="0.055"/>
        </geometry>
      </collision>
      <collision group="other">
        <origin rpy="1.57080 1.57080 0.0" xyz="0.0 -0.035 0"/>
        <geometry>
          <cylinder length="0.075" radius="0.055"/>
        </geometry>
      </collision>
   </link>

   <link name="limb3_link5">
      <inertial>
        <mass value="0.428770" />
        <origin xyz="-0.050402 0.012816 0.000000" rpy="0 0 0" />
        <inertia ixx="0.000670" ixy="0.000062" ixz="0.000000" iyy="0.000955" iyz="0.000000" izz=" 0.000726" />
      </inertial>
      <visual>
        <origin xyz="0.000000 0 0" rpy="0 0 0" />
        <geometry>
           <mesh filename="./stl/robosim_pitch_link.stl" scale="1 1 1" />
        </geometry>
      </visual>
      <collision group="other">
        <origin rpy="3.1415 -1.57080 0" xyz="-0.07 0 0"/>
        <geometry>
          <cylinder length="0.07" radius="0.055"/>
        </geometry>
      </collision>
   </link>

   <link name="limb3_link6">
      <inertial>
        <mass value="4.078540" />
        <origin xyz="0.066970 -0.090099 -0.000084" rpy="0 0 0" />
        <inertia ixx="0.010580" ixy="-0.008765" ixz="-0.000002" iyy="0.025014" iyz="0.000007" izz="0.031182" />
      </inertial>
      <visual>
        <origin xyz="0.000000 0 0" rpy="0 0 0" />
        <geometry>
           <mesh filename="./stl/robosim_roll_link_w_wheel.stl" scale="1 1 1" />
        </geometry>
      </visual>
      <collision group="other">
        <origin rpy="3.1415 -1.57080 0" xyz="0.105 -0.12 0"/>
        <geometry>
          <cylinder length="0.32" radius="0.055"/>
        </geometry>
      </collision>
      <collision group="other">
        <origin rpy="1.57080 1.57080 0.0" xyz="0.0 -0.035 0"/>
        <geometry>
          <cylinder length="0.075" radius="0.055"/>
        </geometry>
      </collision>
      <collision group="other">
        <origin rpy="1.57080 1.57080 0.0" xyz="0.0 -0.19 0"/>
        <geometry>
          <cylinder length="0.0375" radius="0.080"/>
        </geometry>
      </collision>
   </link>
   
   <link name="limb3_ftadapter_link">
      <inertial>
        <mass value="0.253735" />
        <origin xyz="-0.00531 -0.00060 -0.001873" rpy="0 0 0" />
        <inertia ixx="0.00042" ixy="0.00000" ixz="0.0000" iyy="0.00024" iyz="0.00000" izz="0.00023" />
      </inertial>
      <visual>
         <origin xyz="0 0 0" rpy="0 0 0" />
         <geometry>
            <mesh filename="./stl/robosim_ft_adapter.stl" scale="1 1 1" />
         </geometry>
      </visual>   
   </link>

   <link name="limb3_ft_link">
      <inertial>
        <mass value="0.195418" />
        <origin xyz="-0.000135 0.000118 0.000084" rpy="0 0 0" />
        <inertia ixx="0.000086" ixy="0.000" ixz="0.0000" iyy="0.000056" iyz="0.000000" izz="0.000057" />
      </inertial>
      <visual>
         <origin xyz="0 0 0" rpy="0 0 0" />
         <geometry>
            <mesh filename="./stl/robosim_force_torque_sensor.stl" scale="1 1 1" />
         </geometry>
      </visual>
   </link>

   <link name="limb3_link7">
      <inertial>
        <mass value="3.1775" />
        <origin xyz="-0.005260 0.042308 0.000088" rpy="0 0 0" />
        <inertia ixx="0.010977" ixy="0.000702" ixz="0.000026" iyy="0.005330" iyz="-0.000028" izz=" 0.011405" />
      </inertial>
      <visual>
        <origin xyz="0.12024 0 0" rpy="0 0 0" />
        <geometry>
           <mesh filename="./stl/robosim_wheel_mount.stl" scale="1 1 1" />
        </geometry>
      </visual>
      <collision group="other">
        <origin rpy="-1.57080 0 0" xyz="0.12024 0.02 0"/>
        <geometry>
          <cylinder length="0.175" radius="0.0545"/>
        </geometry>
      </collision>
   </link>

  <link name="limb3_link8">
    <inertial>
      <mass value="1.499326" />
      <origin xyz="0.0 0.0 -0.000229" rpy="0 0 0" />
      <inertia ixx="0.006378" ixy="0.000000" ixz="0.000000" iyy="0.006377" iyz="0.000000" izz="0.009155" />
    </inertial>
    <visual>
      <origin xyz="0.0 0 0" rpy="0 0 0" />
      <geometry>
         <mesh filename="./stl/robosim_wheel.stl" scale="1 1 1" />
      </geometry>
    </visual>
    <collision group="other">
      <origin xyz="0.0 0 0" rpy="0 0 0" />
      <geometry>
         <cylinder length="0.123" radius="0.12" />
      </geometry>
    </collision>
  </link>

   <joint name="limb3_joint0" type="fixed">
      <origin xyz="-0.29326 -0.20940 0.03650"  rpy="0.00000 -1.57080 2.87979" />
      <parent link="torso" />
      <child link="limb3_link0" />
      <axis xyz="0 0 1" />
      <limit effort="1000.0" lower="-3.4906" upper="3.4906" velocity="0.5"/>
      <dynamics damping="0" friction="0"/>
   </joint>

   <joint name="limb3_joint1" type="revolute">
      <origin xyz="0.17203 0.00000 0.00000"  rpy="3.14159 -0.00000 0.00000" />
      <axis xyz="1 0 0" />
      <parent link="limb3_link0" />
      <child link="limb3_link1" />
      <limit effort="1000.0" lower="-6.283185" upper="6.283185" velocity="0.5"/>
      <dynamics damping="1.000000" friction="10.000000"/>
   </joint>

   <joint name="limb3_joint2" type="revolute">
      <origin xyz="0.00000 0.00000 0.00000"  rpy="0.00000 -0.00000 0.00000" />
      <axis xyz="0 -1 0" />
      <parent link="limb3_link1" />
      <child link="limb3_link2" />
      <limit effort="1000.0" lower="-6.283185" upper="6.283185" velocity="0.5"/>
      <dynamics damping="1.000000" friction="10.000000"/>
   </joint>

   <joint name="limb3_joint3" type="revolute">
      <origin xyz="0.28650 -0.11700 0.00000"  rpy="0.00000 -0.00000 0.00000" />
      <axis xyz="1 0 0" />
      <parent link="limb3_link2" />
      <child link="limb3_link3" />
      <limit effort="1000.0" lower="-6.283185" upper="6.283185" velocity="0.5"/>
      <dynamics damping="1.000000" friction="10.000000"/>
   </joint>

   <joint name="limb3_joint4" type="revolute">
      <origin xyz="0.00000 0.00000 0.00000"  rpy="0.00000 -0.00000 0.00000" />
      <axis xyz="0 -1 0" />
      <parent link="limb3_link3" />
      <child link="limb3_link4" />
      <limit effort="1000.0" lower="-6.283185" upper="6.283185" velocity="0.5"/>
      <dynamics damping="1.000000" friction="10.000000"/>
   </joint>

   <joint name="limb3_joint5" type="revolute">
      <origin xyz="0.28650 -0.11700 0.00000"  rpy="0.00000 -0.00000 0.00000" />
      <axis xyz="1 0 0" />
      <parent link="limb3_link4" />
      <child link="limb3_link5" />
      <limit effort="1000.0" lower="-6.283185" upper="6.283185" velocity="0.5"/>
      <dynamics damping="1.000000" friction="10.000000"/>
   </joint>

   <joint name="limb3_joint6" type="revolute">
      <origin xyz="0.00000 0.00000 0.00000"  rpy="0.00000 -0.00000 0.00000" />
      <axis xyz="0 -1 0" />
      <parent link="limb3_link5" />
      <child link="limb3_link6" />
      <limit effort="1000.0" lower="-6.283185" upper="6.283185" velocity="0.5"/>
      <dynamics damping="1.000000" friction="10.000000"/>
   </joint>
   
   <joint name="limb3_ftadapter_joint" type="fixed">
      <origin xyz="0.20739 -0.121 0.0"  rpy="0.00000 0.00000 0.00000" />
      <axis xyz="1 0 0" />
      <parent link="limb3_link6" />
      <child link="limb3_ftadapter_link" />
   </joint>  

   <joint name="limb3_ft_joint" type="fixed">
      <origin xyz="0.0263755 0.0 0.0"  rpy="0.00000 0.00000 0.00000" />
      <axis xyz="1 0 0" />
      <parent link="limb3_ftadapter_link" />
      <child link="limb3_ft_link" />
   </joint>

   <joint name="limb3_joint7" type="revolute">
      <origin xyz="0.19250 -0.11700 0.00000"  rpy="0.00000 -0.00000 0.00000" />
      <axis xyz="1 0 0" />
      <parent link="limb3_link6" />
      <child link="limb3_link7" />
      <limit effort="1000.0" lower="-6.283185" upper="6.283185" velocity="0.5"/>
      <dynamics damping="1.000000" friction="10.000000"/>
   </joint>

   <joint name="limb3_joint8" type="revolute">
      <origin xyz="0.12024 0.172 0.0"  rpy="-1.57 0.0 0.00" />
      <axis xyz="0 0 1" />
      <parent link="limb3_link7" />
      <child link="limb3_link8" />
      <limit effort="1000.0" lower="-2e19" upper="2e19" velocity="0.5"/>
      <dynamics damping="1.000000" friction="10.000000"/>
   </joint>

   <link name="limb4_link0">
      <inertial>
        <mass value="0.000000" />
        <origin xyz="0.000000 0.000000 0.000000" rpy="0 0 0" />
        <inertia ixx="0.000000" ixy="0.000000" ixz="0.000000" iyy="0.000000" iyz="0.000000" izz="0.000000" />
      </inertial>
      <visual>
        <origin xyz="0.000000 0 0" rpy="0 0 0" />
        <geometry>
           <mesh filename="./stl/robosim_fts.stl" scale="1 1 1" />
        </geometry>
      </visual>
      <collision group="other">
        <origin rpy="3.1415 -1.57080 0" xyz="-.025 0 0"/>
        <geometry>
          <cylinder length="0.145" radius="0.05"/>
        </geometry>
      </collision>
   </link>

   <link name="limb4_link1">
      <inertial>
        <mass value="0.428770" />
        <origin xyz="-0.050402 0.012816 0.000000" rpy="0 0 0" />
        <inertia ixx="0.000670" ixy="0.000062" ixz="0.000000" iyy="0.000955" iyz="0.000000" izz=" 0.000726" />
      </inertial>
      <visual>
        <origin xyz="0.000000 0 0" rpy="0 0 0" />
        <geometry>
           <mesh filename="./stl/robosim_pitch_link.stl" scale="1 1 1" />
        </geometry>
      </visual>
      <collision group="other">
        <origin rpy="3.1415 -1.57080 0" xyz="-0.07 0 0"/>
        <geometry>
          <cylinder length="0.07" radius="0.055"/>
        </geometry>
      </collision>
   </link>

   <link name="limb4_link2">
      <inertial>
        <mass value="4.078540" />
        <origin xyz="0.066970 -0.090099 -0.000084" rpy="0 0 0" />
        <inertia ixx="0.010580" ixy="-0.008765" ixz="-0.000002" iyy="0.025014" iyz="0.000007" izz="0.031182" />
      </inertial>
      <visual>
        <origin xyz="0.000000 0 0" rpy="0 0 0" />
        <geometry>
           <mesh filename="./stl/robosim_roll_link.stl" scale="1 1 1" />
        </geometry>
      </visual>
      <collision group="other">
        <origin rpy="3.1415 -1.57080 0" xyz="0.065 -0.12 0"/>
        <geometry>
          <cylinder length="0.24" radius="0.055"/>
        </geometry>
      </collision>
      <collision group="other">
        <origin rpy="1.57080 1.57080 0.0" xyz="0.0 -0.035 0"/>
        <geometry>
          <cylinder length="0.075" radius="0.055"/>
        </geometry>
      </collision>
   </link>

   <link name="limb4_link3">
      <inertial>
        <mass value="0.428770" />
        <origin xyz="-0.050402 0.012816 0.000000" rpy="0 0 0" />
        <inertia ixx="0.000670" ixy="0.000062" ixz="0.000000" iyy="0.000955" iyz="0.000000" izz=" 0.000726" />
      </inertial>
      <visual>
        <origin xyz="0.000000 0 0" rpy="0 0 0" />
        <geometry>
           <mesh filename="./stl/robosim_pitch_link.stl" scale="1 1 1" />
        </geometry>
      </visual>
      <collision group="other">
        <origin rpy="3.1415 -1.57080 0" xyz="-0.07 0 0"/>
        <geometry>
          <cylinder length="0.07" radius="0.055"/>
        </geometry>
      </collision>
   </link>

   <link name="limb4_link4">
      <inertial>
        <mass value="4.078540" />
        <origin xyz="0.066970 -0.090099 -0.000084" rpy="0 0 0" />
        <inertia ixx="0.010580" ixy="-0.008765" ixz="-0.000002" iyy="0.025014" iyz="0.000007" izz="0.031182" />
      </inertial>
      <visual>
        <origin xyz="0.000000 0 0" rpy="0 0 0" />
        <geometry>
           <mesh filename="./stl/robosim_roll_link.stl" scale="1 1 1" />
        </geometry>
      </visual>
      <collision group="other">
        <origin rpy="3.1415 -1.57080 0" xyz="0.065 -0.12 0"/>
        <geometry>
          <cylinder length="0.24" radius="0.055"/>
        </geometry>
      </collision>
      <collision group="other">
        <origin rpy="1.57080 1.57080 0.0" xyz="0.0 -0.035 0"/>
        <geometry>
          <cylinder length="0.075" radius="0.055"/>
        </geometry>
      </collision>
   </link>

   <link name="limb4_link5">
      <inertial>
        <mass value="0.428770" />
        <origin xyz="-0.050402 0.012816 0.000000" rpy="0 0 0" />
        <inertia ixx="0.000670" ixy="0.000062" ixz="0.000000" iyy="0.000955" iyz="0.000000" izz=" 0.000726" />
      </inertial>
      <visual>
        <origin xyz="0.000000 0 0" rpy="0 0 0" />
        <geometry>
           <mesh filename="./stl/robosim_pitch_link.stl" scale="1 1 1" />
        </geometry>
      </visual>
      <collision group="other">
        <origin rpy="3.1415 -1.57080 0" xyz="-0.07 0 0"/>
        <geometry>
          <cylinder length="0.07" radius="0.055"/>
        </geometry>
      </collision>
   </link>

   <link name="limb4_link6">
      <inertial>
        <mass value="4.078540" />
        <origin xyz="0.066970 -0.090099 -0.000084" rpy="0 0 0" />
        <inertia ixx="0.010580" ixy="-0.008765" ixz="-0.000002" iyy="0.025014" iyz="0.000007" izz="0.031182" />
      </inertial>
      <visual>
        <origin xyz="0.000000 0 0" rpy="0 0 0" />
        <geometry>
           <mesh filename="./stl/robosim_roll_link.stl" scale="1 1 1" />
        </geometry>
      </visual>
      <collision group="other">
        <origin rpy="3.1415 -1.57080 0" xyz="0.105 -0.12 0"/>
        <geometry>
          <cylinder length="0.32" radius="0.055"/>
        </geometry>
      </collision>
      <collision group="other">
        <origin rpy="1.57080 1.57080 0.0" xyz="0.0 -0.035 0"/>
        <geometry>
          <cylinder length="0.075" radius="0.055"/>
        </geometry>
      </collision>
   </link>

   <link name="limb4_ftadapter_link">
      <inertial>
        <mass value="0.253735" />
        <origin xyz="-0.00531 -0.00060 -0.001873" rpy="0 0 0" />
        <inertia ixx="0.00042" ixy="0.00000" ixz="0.0000" iyy="0.00024" iyz="0.00000" izz="0.00023" />
      </inertial>
      <visual>
         <origin xyz="0 0 0" rpy="0 0 0" />
         <geometry>
            <mesh filename="./stl/robosim_ft_adapter.stl" scale="1 1 1" />
         </geometry>
      </visual>   
   </link>
   
   <link name="limb4_ft_link">
      <inertial>
        <mass value="0.195418" />
        <origin xyz="-0.000135 0.000118 0.000084" rpy="0 0 0" />
        <inertia ixx="0.000086" ixy="0.000" ixz="0.0000" iyy="0.000056" iyz="0.000000" izz="0.000057" />
      </inertial>
      <visual>
         <origin xyz="0.0 0.0 0.0" rpy="0.00000 0.00000 0.00000" />
         <geometry>
            <mesh filename="./stl/robosim_force_torque_sensor.stl" scale="1 1 1" />
         </geometry>
      </visual>   
   </link>

   <link name="limb4_link7">
      <inertial>
        <mass value="3.1775" />
        <origin xyz="-0.005260 0.042308 0.000088" rpy="0 0 0" />
        <inertia ixx="0.010977" ixy="0.000702" ixz="0.000026" iyy="0.005330" iyz="-0.000028" izz=" 0.011405" />
      </inertial>
      <visual>
        <origin xyz="0.12024 0 0" rpy="0 0 0" />
        <geometry>
           <mesh filename="./stl/robosim_wheel_mount.stl" scale="1 1 1" />
        </geometry>
      </visual>
      <collision group="other">
        <origin rpy="-1.57080 0 0" xyz="0.12024 0.02 0"/>
        <geometry>
          <cylinder length="0.175" radius="0.0545"/>
        </geometry>
      </collision>
   </link>

  <link name="limb4_link8">
    <inertial>
      <mass value="1.499326" />
      <origin xyz="0.0 0.0 -0.000229" rpy="0 0 0" />
      <inertia ixx="0.006378" ixy="0.000000" ixz="0.000000" iyy="0.006377" iyz="0.000000" izz="0.009155" />
    </inertial>
    <visual>
      <origin xyz="0.0 0 0" rpy="0 0 0" />
      <geometry>
         <mesh filename="./stl/robosim_wheel.stl" scale="1 1 1" />
      </geometry>
    </visual>
    <collision group="other">
      <origin xyz="0.0 0 0" rpy="0 0 0" />
      <geometry>
         <cylinder length="0.123" radius="0.12" />
      </geometry>
    </collision>
   </link>

   <joint name="limb4_joint0" type="fixed">
      <origin xyz="0.29326 -0.20940 0.03650"  rpy="0.00000 -1.57080 3.40339" />
      <parent link="torso" />
      <child link="limb4_link0" />
      <axis xyz="0 0 1" />
      <limit effort="1000.0" lower="-3.4906" upper="3.4906" velocity="0.5"/>
      <dynamics damping="0" friction="0"/>
   </joint>

   <joint name="limb4_joint1" type="revolute">
      <origin xyz="0.17203 0.00000 0.00000"  rpy="3.14159 -0.00000 0.00000" />
      <axis xyz="1 0 0" />
      <parent link="limb4_link0" />
      <child link="limb4_link1" />
      <limit effort="1000.0" lower="-6.283185" upper="6.283185" velocity="0.5"/>
      <dynamics damping="1.000000" friction="10.000000"/>
   </joint>

   <joint name="limb4_joint2" type="revolute">
      <origin xyz="0.00000 0.00000 0.00000"  rpy="0.00000 -0.00000 0.00000" />
      <axis xyz="0 -1 0" />
      <parent link="limb4_link1" />
      <child link="limb4_link2" />
      <limit effort="1000.0" lower="-6.283185" upper="6.283185" velocity="0.5"/>
      <dynamics damping="1.000000" friction="10.000000"/>
   </joint>

   <joint name="limb4_joint3" type="revolute">
      <origin xyz="0.28650 -0.11700 0.00000"  rpy="0.00000 -0.00000 0.00000" />
      <axis xyz="1 0 0" />
      <parent link="limb4_link2" />
      <child link="limb4_link3" />
      <limit effort="1000.0" lower="-6.283185" upper="6.283185" velocity="0.5"/>
      <dynamics damping="1.000000" friction="10.000000"/>
   </joint>

   <joint name="limb4_joint4" type="revolute">
      <origin xyz="0.00000 0.00000 0.00000"  rpy="0.00000 -0.00000 0.00000" />
      <axis xyz="0 -1 0" />
      <parent link="limb4_link3" />
      <child link="limb4_link4" />
      <limit effort="1000.0" lower="-6.283185" upper="6.283185" velocity="0.5"/>
      <dynamics damping="1.000000" friction="10.000000"/>
   </joint>

   <joint name="limb4_joint5" type="revolute">
      <origin xyz="0.28650 -0.11700 0.00000"  rpy="0.00000 -0.00000 0.00000" />
      <axis xyz="1 0 0" />
      <parent link="limb4_link4" />
      <child link="limb4_link5" />
      <limit effort="1000.0" lower="-6.283185" upper="6.283185" velocity="0.5"/>
      <dynamics damping="1.000000" friction="10.000000"/>
   </joint>
   
   <joint name="limb4_joint6" type="revolute">
      <origin xyz="0.00000 0.00000 0.00000"  rpy="0.00000 -0.00000 0.00000" />
      <axis xyz="0 -1 0" />
      <parent link="limb4_link5" />
      <child link="limb4_link6" />
      <limit effort="1000.0" lower="-6.283185" upper="6.283185" velocity="0.5"/>
      <dynamics damping="1.000000" friction="10.000000"/>
   </joint>
   
   <joint name="limb4_ftadapter_joint" type="fixed">
      <origin xyz="0.20739 -0.121 0.0"  rpy="0.00000 0.00000 0.00000" />
      <axis xyz="1 0 0" />
      <parent link="limb4_link6" />
      <child link="limb4_ftadapter_link" />
   </joint>  

   <joint name="limb4_ft_joint" type="fixed">
      <origin xyz="0.0263755 0.0 0.0"  rpy="0.00000 0.00000 0.00000" />
      <axis xyz="1 0 0" />
      <parent link="limb4_ftadapter_link" />
      <child link="limb4_ft_link" />
   </joint>
   
   <joint name="limb4_joint7" type="revolute">
      <origin xyz="0.19250 -0.11700 0.00000"  rpy="0.00000 -0.00000 0.00000" />
      <axis xyz="1 0 0" />
      <parent link="limb4_link6" />
      <child link="limb4_link7" />
      <limit effort="1000.0" lower="-6.283185" upper="6.283185" velocity="0.5"/>
      <dynamics damping="1.000000" friction="10.000000"/>
   </joint>

   <joint name="limb4_joint8" type="revolute">
      <origin xyz="0.12024 0.172 0.0"  rpy="-1.57 0.0 0.00" />
      <axis xyz="0 0 1" />
      <parent link="limb4_link7" />
      <child link="limb4_link8" />
      <limit effort="1000.0" lower="-2e19" upper="2e19" velocity="0.5"/>
      <dynamics damping="1.000000" friction="10.000000"/>
   </joint>

</robot>
